<?xml version="1.0"?>
<robot xmlns:xacro="http://www.ros.org/wiki/xacro"  >

    <xacro:include filename="inertial_macros.xacro"/>

    <!-- Pre-defined colors -->
    <material name="white">
        <color rgba="1 1 1 1"/>
    </material>

    <material name="orange">
        <color rgba="1 0.3 0.1 1"/>
    </material>

    <material name="blue">
        <color rgba="0.2 0.2 1 1"/>
    </material>

    <material name="black">
        <color rgba="0 0 0 1"/>
    </material>

    <material name="red">
        <color rgba="1 0 0 1"/>
    </material>
    
    <!-- END Pre-defined colors -->

    <!-- Base Link -->
    <link name="base_link">
    
    </link>

    <!-- Base Footprint Link -->
    <joint name="base_footprint_joint" type="fixed">
        <parent link="base_link"/>
        <child link="base_footprint"/>
        <origin xyz="0 0 0" rpy="0 0 0"/>    
    </joint>

    <link name="base_footprint">
    </link>

    <!-- Chassis link -->
    <joint name="chassis_joint" type="fixed">
        <parent link="base_link"/>
        <child link="chassis"/>
        <origin xyz="-0.1624 0 0"/>
    </joint>

    <link name="chassis">
        <visual>
            <origin xyz="0.104 0 0.02725" rpy="0 0 0"/>
            <geometry>
                <box size="0.208 0.208 0.0545"/>
            </geometry>
            <material name="white"/>
        </visual>

        <collision>
            <origin xyz="0.104 0 0.02725" rpy="0 0 0"/>
            <geometry>
                <box size="0.208 0.208 0.0545"/>
            </geometry>
            <material name="white"/>
        </collision>

        <xacro:inertial_box mass="0.5" x="0.3" y="0.3" z="0.15">
            <origin xyz="0.15 0 0.075" rpy="0 0 0"/>
        </xacro:inertial_box>
    </link>

    <gazebo reference="chassis">
        <material>Gazebo/White</material>
    </gazebo>

    <!-- Left Wheel Link -->
    <joint name="left_wheel_joint" type="continuous">
        <parent link="base_link"/>
        <child link="left_wheel"/>
        <origin xyz="0 0.12315 0.019" rpy="-${pi/2} 0 0"/>
        <axis xyz="0 0 1"/>
    </joint>

    <link name="left_wheel">
        <visual>
            <geometry>
                <cylinder radius="0.03365" length="0.0267"/>/>
            </geometry>
            <material name="blue"/>
        </visual>

        <collision>
            <geometry>
                <cylinder radius="0.03365" length="0.0267"/>/>
            </geometry>
            <material name="blue"/>
        </collision>

        <xacro:inertial_cylinder mass="0.1" length="0.0267" radius="0.03365">
            <origin xyz="0 0 0" rpy="0 0 0"/>
        </xacro:inertial_cylinder>
    </link>

    <gazebo reference="left_wheel">
        <material>Gazebo/Blue</material>
    </gazebo>

    <!-- Right Wheel Link -->
    <joint name="right_wheel_joint" type="continuous">
        <parent link="base_link"/>
        <child link="right_wheel"/>
        <origin xyz="0 -0.12315 0.019" rpy="${pi/2} 0 0"/>
        <axis xyz="0 0 -1"/>
    </joint>

    <link name="right_wheel">
        <visual>
            <geometry>
                <cylinder length="0.0267" radius="0.03365" />/>
            </geometry>
            <material name="blue"/>
        </visual>

        <collision>
            <geometry>
                <cylinder length="0.0267" radius="0.03365" />/>
            </geometry>
            <material name="blue"/>
        </collision>

        <xacro:inertial_cylinder mass="0.1" length="0.0267" radius="0.03365">
            <origin xyz="0 0 0" rpy="0 0 0"/>
        </xacro:inertial_cylinder>
    </link>

    <gazebo reference="right_wheel">
        <material>Gazebo/Blue</material>
    </gazebo>

    <!-- Castor Wheel Link -->
    <joint name="castor_wheel_joint" type="fixed">
        <parent link="chassis"/>
        <child link="castor_wheel"/>
        <origin xyz="0.02 0 0"/>
    </joint>

    <link name="castor_wheel">
        <visual>
            <geometry>
                <sphere radius="0.0171"/>
            </geometry>
            <material name="black"/>
        </visual>

        <collision>
            <geometry>
                <sphere radius="0.0171"/>
            </geometry>
            <material name="black"/>
        </collision>

        <xacro:inertial_sphere mass="0.1" radius="0.0171">
            <origin xyz="0 0 0" rpy="0 0 0"/>
        </xacro:inertial_sphere>
    </link>

    <gazebo reference="castor_wheel">
        <material>Gazebo/Black</material>
        <mu1 value="0.001"/>
        <mu2 value="0.001"/>   
    </gazebo>

</robot>